[2025-02-13T04:02:46.843+0000] {local_task_job_runner.py:123} INFO - ::group::Pre task execution logs
[2025-02-13T04:02:46.879+0000] {taskinstance.py:2614} INFO - Dependencies all met for dep_context=non-requeueable deps ti=<TaskInstance: workflow_1.upload_data_to_s3 manual__2025-02-13T04:02:20.581738+00:00 [queued]>
[2025-02-13T04:02:46.903+0000] {taskinstance.py:2614} INFO - Dependencies all met for dep_context=requeueable deps ti=<TaskInstance: workflow_1.upload_data_to_s3 manual__2025-02-13T04:02:20.581738+00:00 [queued]>
[2025-02-13T04:02:46.904+0000] {taskinstance.py:2867} INFO - Starting attempt 1 of 1
[2025-02-13T04:02:46.953+0000] {taskinstance.py:2890} INFO - Executing <Task(PythonOperator): upload_data_to_s3> on 2025-02-13 04:02:20.581738+00:00
[2025-02-13T04:02:46.961+0000] {standard_task_runner.py:104} INFO - Running: ['airflow', 'tasks', 'run', 'workflow_1', 'upload_data_to_s3', 'manual__2025-02-13T04:02:20.581738+00:00', '--job-id', '18', '--raw', '--subdir', 'DAGS_FOLDER/retry.py', '--cfg-path', '/tmp/tmp07m5140x']
[2025-02-13T04:02:46.964+0000] {standard_task_runner.py:105} INFO - Job 18: Subtask upload_data_to_s3
[2025-02-13T04:02:46.965+0000] {logging_mixin.py:190} WARNING - /home/airflow/.local/lib/python3.12/site-packages/airflow/task/task_runner/standard_task_runner.py:70 DeprecationWarning: This process (pid=162) is multi-threaded, use of fork() may lead to deadlocks in the child.
[2025-02-13T04:02:46.966+0000] {standard_task_runner.py:72} INFO - Started process 172 to run task
[2025-02-13T04:02:47.104+0000] {task_command.py:467} INFO - Running <TaskInstance: workflow_1.upload_data_to_s3 manual__2025-02-13T04:02:20.581738+00:00 [running]> on host f6cd8c636678
[2025-02-13T04:02:47.307+0000] {taskinstance.py:3134} INFO - Exporting env vars: AIRFLOW_CTX_DAG_OWNER='airflow' AIRFLOW_CTX_DAG_ID='workflow_1' AIRFLOW_CTX_TASK_ID='upload_data_to_s3' AIRFLOW_CTX_EXECUTION_DATE='2025-02-13T04:02:20.581738+00:00' AIRFLOW_CTX_TRY_NUMBER='1' AIRFLOW_CTX_DAG_RUN_ID='manual__2025-02-13T04:02:20.581738+00:00'
[2025-02-13T04:02:47.309+0000] {taskinstance.py:732} INFO - ::endgroup::
[2025-02-13T04:02:47.330+0000] {taskinstance.py:3313} ERROR - Task failed with exception
Traceback (most recent call last):
  File "/home/airflow/.local/lib/python3.12/site-packages/airflow/models/taskinstance.py", line 768, in _execute_task
    result = _execute_callable(context=context, **execute_callable_kwargs)
             ^^^^^^^^^^^^^^^^^^^^^^^^^^^^^^^^^^^^^^^^^^^^^^^^^^^^^^^^^^^^^
  File "/home/airflow/.local/lib/python3.12/site-packages/airflow/models/taskinstance.py", line 734, in _execute_callable
    return ExecutionCallableRunner(
           ^^^^^^^^^^^^^^^^^^^^^^^^
  File "/home/airflow/.local/lib/python3.12/site-packages/airflow/utils/operator_helpers.py", line 252, in run
    return self.func(*args, **kwargs)
           ^^^^^^^^^^^^^^^^^^^^^^^^^^
  File "/home/airflow/.local/lib/python3.12/site-packages/airflow/models/baseoperator.py", line 424, in wrapper
    return func(self, *args, **kwargs)
           ^^^^^^^^^^^^^^^^^^^^^^^^^^^
  File "/home/airflow/.local/lib/python3.12/site-packages/airflow/operators/python.py", line 238, in execute
    return_value = self.execute_callable()
                   ^^^^^^^^^^^^^^^^^^^^^^^
  File "/home/airflow/.local/lib/python3.12/site-packages/airflow/operators/python.py", line 256, in execute_callable
    return runner.run(*self.op_args, **self.op_kwargs)
           ^^^^^^^^^^^^^^^^^^^^^^^^^^^^^^^^^^^^^^^^^^^
  File "/home/airflow/.local/lib/python3.12/site-packages/airflow/utils/operator_helpers.py", line 252, in run
    return self.func(*args, **kwargs)
           ^^^^^^^^^^^^^^^^^^^^^^^^^^
  File "/opt/airflow/dags/retry.py", line 35, in upload_data_to_s3
    s3_hook.load_file(file_name=filename,key=key,bucket_name=bucket_name)
  File "/home/airflow/.local/lib/python3.12/site-packages/airflow/providers/amazon/aws/hooks/s3.py", line 137, in wrapper
    bound_args = function_signature.bind(*args, **kwargs)
                 ^^^^^^^^^^^^^^^^^^^^^^^^^^^^^^^^^^^^^^^^
  File "/usr/local/lib/python3.12/inspect.py", line 3277, in bind
    return self._bind(args, kwargs)
           ^^^^^^^^^^^^^^^^^^^^^^^^
  File "/usr/local/lib/python3.12/inspect.py", line 3190, in _bind
    raise TypeError(msg) from None
TypeError: missing a required argument: 'filename'
[2025-02-13T04:02:47.362+0000] {taskinstance.py:1226} INFO - Marking task as FAILED. dag_id=workflow_1, task_id=upload_data_to_s3, run_id=manual__2025-02-13T04:02:20.581738+00:00, execution_date=20250213T040220, start_date=20250213T040246, end_date=20250213T040247
[2025-02-13T04:02:47.469+0000] {taskinstance.py:341} INFO - ::group::Post task execution logs
[2025-02-13T04:02:47.470+0000] {standard_task_runner.py:124} ERROR - Failed to execute job 18 for task upload_data_to_s3 (missing a required argument: 'filename'; 172)
Traceback (most recent call last):
  File "/home/airflow/.local/lib/python3.12/site-packages/airflow/task/task_runner/standard_task_runner.py", line 117, in _start_by_fork
    ret = args.func(args, dag=self.dag)
          ^^^^^^^^^^^^^^^^^^^^^^^^^^^^^
  File "/home/airflow/.local/lib/python3.12/site-packages/airflow/cli/cli_config.py", line 49, in command
    return func(*args, **kwargs)
           ^^^^^^^^^^^^^^^^^^^^^
  File "/home/airflow/.local/lib/python3.12/site-packages/airflow/utils/cli.py", line 116, in wrapper
    return f(*args, **kwargs)
           ^^^^^^^^^^^^^^^^^^
  File "/home/airflow/.local/lib/python3.12/site-packages/airflow/cli/commands/task_command.py", line 483, in task_run
    task_return_code = _run_task_by_selected_method(args, _dag, ti)
                       ^^^^^^^^^^^^^^^^^^^^^^^^^^^^^^^^^^^^^^^^^^^^
  File "/home/airflow/.local/lib/python3.12/site-packages/airflow/cli/commands/task_command.py", line 256, in _run_task_by_selected_method
    return _run_raw_task(args, ti)
           ^^^^^^^^^^^^^^^^^^^^^^^
  File "/home/airflow/.local/lib/python3.12/site-packages/airflow/cli/commands/task_command.py", line 341, in _run_raw_task
    return ti._run_raw_task(
           ^^^^^^^^^^^^^^^^^
  File "/home/airflow/.local/lib/python3.12/site-packages/airflow/utils/session.py", line 97, in wrapper
    return func(*args, session=session, **kwargs)
           ^^^^^^^^^^^^^^^^^^^^^^^^^^^^^^^^^^^^^^
  File "/home/airflow/.local/lib/python3.12/site-packages/airflow/models/taskinstance.py", line 3006, in _run_raw_task
    return _run_raw_task(
           ^^^^^^^^^^^^^^
  File "/home/airflow/.local/lib/python3.12/site-packages/airflow/models/taskinstance.py", line 274, in _run_raw_task
    TaskInstance._execute_task_with_callbacks(
  File "/home/airflow/.local/lib/python3.12/site-packages/airflow/models/taskinstance.py", line 3161, in _execute_task_with_callbacks
    result = self._execute_task(context, task_orig)
             ^^^^^^^^^^^^^^^^^^^^^^^^^^^^^^^^^^^^^^
  File "/home/airflow/.local/lib/python3.12/site-packages/airflow/models/taskinstance.py", line 3185, in _execute_task
    return _execute_task(self, context, task_orig)
           ^^^^^^^^^^^^^^^^^^^^^^^^^^^^^^^^^^^^^^^
  File "/home/airflow/.local/lib/python3.12/site-packages/airflow/models/taskinstance.py", line 768, in _execute_task
    result = _execute_callable(context=context, **execute_callable_kwargs)
             ^^^^^^^^^^^^^^^^^^^^^^^^^^^^^^^^^^^^^^^^^^^^^^^^^^^^^^^^^^^^^
  File "/home/airflow/.local/lib/python3.12/site-packages/airflow/models/taskinstance.py", line 734, in _execute_callable
    return ExecutionCallableRunner(
           ^^^^^^^^^^^^^^^^^^^^^^^^
  File "/home/airflow/.local/lib/python3.12/site-packages/airflow/utils/operator_helpers.py", line 252, in run
    return self.func(*args, **kwargs)
           ^^^^^^^^^^^^^^^^^^^^^^^^^^
  File "/home/airflow/.local/lib/python3.12/site-packages/airflow/models/baseoperator.py", line 424, in wrapper
    return func(self, *args, **kwargs)
           ^^^^^^^^^^^^^^^^^^^^^^^^^^^
  File "/home/airflow/.local/lib/python3.12/site-packages/airflow/operators/python.py", line 238, in execute
    return_value = self.execute_callable()
                   ^^^^^^^^^^^^^^^^^^^^^^^
  File "/home/airflow/.local/lib/python3.12/site-packages/airflow/operators/python.py", line 256, in execute_callable
    return runner.run(*self.op_args, **self.op_kwargs)
           ^^^^^^^^^^^^^^^^^^^^^^^^^^^^^^^^^^^^^^^^^^^
  File "/home/airflow/.local/lib/python3.12/site-packages/airflow/utils/operator_helpers.py", line 252, in run
    return self.func(*args, **kwargs)
           ^^^^^^^^^^^^^^^^^^^^^^^^^^
  File "/opt/airflow/dags/retry.py", line 35, in upload_data_to_s3
    s3_hook.load_file(file_name=filename,key=key,bucket_name=bucket_name)
  File "/home/airflow/.local/lib/python3.12/site-packages/airflow/providers/amazon/aws/hooks/s3.py", line 137, in wrapper
    bound_args = function_signature.bind(*args, **kwargs)
                 ^^^^^^^^^^^^^^^^^^^^^^^^^^^^^^^^^^^^^^^^
  File "/usr/local/lib/python3.12/inspect.py", line 3277, in bind
    return self._bind(args, kwargs)
           ^^^^^^^^^^^^^^^^^^^^^^^^
  File "/usr/local/lib/python3.12/inspect.py", line 3190, in _bind
    raise TypeError(msg) from None
TypeError: missing a required argument: 'filename'
[2025-02-13T04:02:47.504+0000] {local_task_job_runner.py:266} INFO - Task exited with return code 1
[2025-02-13T04:02:47.537+0000] {taskinstance.py:3901} INFO - 0 downstream tasks scheduled from follow-on schedule check
[2025-02-13T04:02:47.540+0000] {local_task_job_runner.py:245} INFO - ::endgroup::
